Workbook

Sheet General Information
B2: PSAP Security Practices — Assessment Matrix
B4: This workbook is a companion to the PSAP Security Practices Posture Assessment report. It documents implementation status at the individual assessment item level and provides quantitative scoring to support baseline tracking, trend analysis, and comparison across future assessment cycles.
B8: Workbook Structure
B9: Question Set — | D9: Contains the 198 assessment items organized by domain and category, along with the assessment question text, PSAP-provided comments and supporting information, the assessed rating for each item, and discrepancy comments where the assessed rating differs from the PSAP's initial self-reported rating.
D12: Ratings use the following scale: - Yes (3) - In Progress (2) - Planned (1) - No (0) - Unknown (0) - Not Applicable (excluded from scoring)
B20: Full Score Table — | D20: Displays rating distribution counts by category and domain, with weighted point totals and maximum possible scores. Items rated 'Not Applicable' are excluded from point calculations.
B23: Domain-Level Score Table — | D23: Summarizes rating distribution, point totals, and maximum possible scores at the domain level.
B25: Bar Chart — | D25: Visualizes domain-level implementation scores as a percentage of maximum possible points, with a target threshold for reference.
B28: Radar Chart — | D28: Visualizes domain-level implementation percentages in a radar (spider) format to illustrate relative strength and coverage across all 13 assessment domains.
B33: Assessment Framework
B35: This assessment is anchored in two complementary references: the NENA Security for Next Generation 9-1-1 Standard (NG-SEC) [NENA-STA-040.2-2024], which defines security outcomes and requirements for NG9-1-1 environments, and NIST Special Publication 800-53 Revision 5, which provides a detailed catalog of security and privacy controls. The 198 assessment items in this workbook are organized across 13 security domains and 51 categories derived from these frameworks.
B40: Scoring
B42: Each assessment item is rated on a 0-3 implementation scale. Point totals are calculated by weighting each rating ('Unknown' = 0, 'No' = 0, 'Planned' = 1, 'In Progress' = 2, 'Yes' = 3) and summing across applicable items. Items rated 'Not Applicable' are excluded from both the point total and the maximum possible score, so that percentages reflect only items within the scope for the assessed environment. The maximum possible score for any category or domain represents full implementation (a rating of 'Yes') for all applicable items.
B47: Target Implementation Threshold
B49: The target implementation threshold defines the minimum acceptable implementation percentage used as a reference point ('Goal') in the Bar Chart and Radar Chart visualizations. This threshold can be configured below and applies uniformly across all domains.
B51: — Target Threshold Value — | E51: 0.5

Sheet PSAP Information
A1: PSAP | C1: Sample County 911 Communications
A2: Address | C2: 100 Public Safety Drive
A3: City/ZIP | C3: Anytown | 00000
A5: PSAP Director | C5: Jane Smith
A6: Director Phone # | C6: 555-000-0000
A7: Director Email | C7: jsmith@samplecounty.gov
A9: Registration Date | C9: 45672
A10: Final Domain Survey Complete | C10: 45689
A11: Site Visit Date
A13: Target Maturity Score | B13: ='General Information'!$E$51 -> 0.5
A15: Domain Survey Information: | C15: Stakeholders providing input: | D15: Date Completed:
A16: Domain 1 | C16: IT Director Director of 911 Operations | D16: 45689
A17: Domain 2 | C17: IT Director Director of 911 Operations | D17: 45689
A18: Domain 3 | C18: IT Director Director of 911 Operations | D18: 45689
A19: Domain 4 | C19: IT Director Director of 911 Operations | D19: 45689
A20: Domain 5 | C20: IT Director Director of 911 Operations | D20: 45689
A21: Domain 6 | C21: IT Director Director of 911 Operations | D21: 45689
A22: Domain 7 | C22: IT Director Director of 911 Operations | D22: 45689
A23: Domain 8 | C23: IT Director Director of 911 Operations | D23: 45689
A24: Domain 9 | C24: IT Director Director of 911 Operations | D24: 45689
A25: Domain 10 | C25: IT Director Director of 911 Operations | D25: 45689
A26: Domain 11 | C26: IT Director Director of 911 Operations | D26: 45689
A27: Domain 12 | C27: IT Director Director of 911 Operations | D27: 45689
A28: Domain 13 | C28: IT Director Director of 911 Operations | D28: 45689

Sheet Question Set
A1: ID | E1: Question Text, Follow Up Question & Implementation Example | F1: Comments & Additional Information | G1: Assessed Rating
B2: 1. Governance, Risk & Strategy
C3: A. Executive Leadership & Resource Allocation
A4: 1A-1 | D4: 1. | E4: Do executive leaders – such as the CEO, City Manager, or Board members – formally review and approve cybersecurity and privacy policies and strategic security plans to ensure legal compliance and alignment with public safety goals? If yes, please list the executives involved and how often these documents are reviewed or updated. (Example: “Our City Manager and Legal Counsel review the policy annually in Q1.”) | F4: Scheduled for a future implementation cycle. | G4: PLANNED
A5: 1A-2 | D5: 2. | E5: Does senior management designate a cybersecurity and privacy lead for your Emergency Communications Center (ECC) or Public Safety Answering Point (PSAP) and allocate appropriate staff resources, tools, and budget to safeguard these mission-critical services? If yes, please name the role or individual and briefly describe the staffing, technology, or budget they’ve been allocated. (Example: “Our Chief Technology Officer is the official ECC/PSAP Security Lead, supported by a three-person team and a dedicated $50K annual budget.”) | F5: Implemented and documented. | G5: YES
A6: 1A-3 | D6: 3. | E6: Do senior leaders regularly monitor emerging threats – such as ransomware or service outages – that could disrupt 9-1-1 or emergency response operations? If yes, please describe how they stay informed and how often they review threat reports. (Example: “They receive a weekly threat summary from our SOC (Security Operations Center) and meet monthly to discuss high-risk alerts.”) | F6: Controls are in place and verified. | G6: YES
C8: B. Policy & Asset Inventory Management
A9: 1B-1 | D9: 1. | E9: Do your emergency communications cybersecurity and privacy policies: * Explicitly reference all applicable laws and regulations (e.g., CJIS, state privacy laws) * Include security controls aligned with the risks identified for your mission- critical systems If yes, please explain which laws you follow and name one or two key controls you’ve implemented. (Example: “We comply with CJIS requirements. We enforce multifactor authentication and daily log reviews for all dispatch consoles.”) | F9: Process is established and followed. | G9: YES
A10: 1B-2 | D10: 2. | E10: Has senior leadership formally approved – and do they oversee – a policy that outlines how you: * Maintain an up-to-date inventory of every 9-1-1 and related system (e.g., call- handling platforms, mapping tools, logging servers) * Regularly review that inventory to support informed decisions and protect sensitive data If yes, please briefly describe where this policy is documented and how reviews are scheduled. (Example: “Our City IT Director signs off on the policy each January. The Operations team updates the inventory quarterly.”) | F10: Not yet implemented. | G10: NO
A11: 1B-3 | D11: 3. | E11: Do you have formal, written plans for systems like CAD (Computer-Aided Dispatch), CPE/CHE (Call Processing/Call Handling Equipment), GIS (Mapping), and others that: * Assign clear roles and responsibilities for each system * Explain how systems are categorized by importance and data sensitivity * Describe how devices connect and exchange information * Are updated following regular risk reviews If yes, please list the systems covered and where the most current version of each plan is stored. (Example: “Our CAD and GIS plans are stored in SharePoint. We update them after our annual risk assessment each October.”) | F11: Identified as a gap; not yet addressed. | G11: NO
C13: C. Role Definition & Governance Oversight
A14: 1C-1 | D14: 1. | E14: Has your organization empowered a senior executive and a formal governance group (e.g., a steering committee or board) to: * Set cybersecurity and privacy priorities * Review performance metrics and reports * Ensure alignment with public safety goals and legal and regulatory requirements If yes, please name the executive role and the governance body, and describe how often they meet. (Example: “The Assistant City Manager chairs our Cyber Risk Committee, which meets quarterly.”) | F14: Practice is mature and consistent. | G14: YES
A15: 1C-2 | D15: 2. | E15: Do the people who “own” your data (e.g., operations managers) and those who “manage” it (e.g., IT staff) participate in a formal data governance process that: * Defines how you classify data by sensitivity (public, internal, confidential) * Sets rules for sharing data internally or with partners * Regularly reviews and updates those policies If yes, please list the roles involved and how frequently your data governance group meets or reviews policies. (Example: “Our Data Governance Board includes the CAD Manager and the CIO. They review classification rules annually.”) | F15: Process does not currently exist. | G15: NO
A16: 1C-3 | D16: 3. | E16: Does your organization employ enough trained personnel, either internally or with contractors, with clear job descriptions, to: * Set up systems securely * Monitor security in real time * Respond to incidents * Perform audit reviews If yes, please describe your security team structure (titles or roles) and approximate staffing levels. (Example: “We have a two-person SOC (Security Operations Center) team, plus one external consultant on retainer.”) | F16: Fully implemented per current policy. | G16: YES
A17: 1C-4 | D17: 4. | E17: Do you have documented roles and processes, including acceptable use rules and background checks where required, for granting, changing, and removing access to: * Critical systems (e.g., dispatch consoles, admin portals) * Secure facilities (e.g., data centers, control rooms) If yes, please outline who approves access and what screening or rules apply. (Example: “Managers approve console access; all new hires undergo a criminal background check.”) | F17: In place; reviewed periodically. | G17: YES
A18: 1C-5 | D18: 5. | E18: Do you have written procedures that cover: * Secure system configuration * System log monitoring * Incident detection and reporting * Risk assessments * Remediation tracking across all 9-1-1 platforms (e.g., call handling, mapping, back-end servers) If yes, please indicate where these documents are stored (e.g., SharePoint folder) and how they’re kept up to date. (Example: “All procedures are in our Policy Manual, updated after each quarterly risk review.”) | F18: Working to formalize this process. | G18: IN PROGRESS
C20: D. Risk Assessment & Management Strategy
A21: 1D-1 | D21: 1. | E21: Do you maintain a written risk management strategy that: * Reflects your organization’s risk appetite (how much risk you’re willing to accept) * Addresses multiple threat vectors (e.g., phishing, malware, supplier issues, and denial-of-service attacks) * Is reviewed and updated on a regular schedule If yes, please note where the strategy is documented and when the last review occurred. (Example: “Our Risk Strategy lives in the Policy Manual; last reviewed January 2025.”) | F21: Documentation is in development. | G21: IN PROGRESS
A22: 1D-2 | D22: 2. | E22: Have you categorized all systems and data sets by their sensitivity and operational criticality – specifically considering Confidentiality, Integrity, and Availability – and used this framework to define risk levels and select appropriate security controls? If yes, please share your categorization scheme (for example, “High, Medium, Low”) and one or two controls you apply at each level. (Example: “‘High Impact’ systems require daily backups and multifactor authentication.”) | F22: No formal controls in place. | G22: NO
A23: 1D-3 | D23: 3. | E23: Does your organization have written policies and procedures that spell out: * Scope – which public safety systems (e.g., CAD, call routing, GIS, etc.) must be assessed * Frequency – how often you run those assessments * Roles – who leads and who supports each assessment * Methods – what tools or techniques are used (e.g., interviews, automated scans, tabletop exercises) If yes, please indicate where these documents are stored and when they were last updated. (Example: “Our Risk Assessment SOP is in SharePoint; it was updated in September 2024.”) | F23: Not currently in scope; noted as a gap. | G23: NO
A24: 1D-4 | D24: 4. | E24: Do you conduct formal risk assessments that: * Identify likely ways an attacker or failure could impact you (e.g., technical flaws, vendor issues, user errors) * Evaluate each risk based on its potential impact on service (slowed or lost dispatch), data (confidentiality breach), or life safety (9-1-1 delays) If yes, please describe which threat categories you cover and how you score their impacts. (Example: “We rate each scenario on a 1–5 scale for service outage and data loss.”) | F24: This has not been established. | G24: NO
A25: 1D-5 | D25: 5. | E25: Do you use the outcomes of your risk assessments to: * Prioritize which systems to monitor more closely * Decide what mitigation steps to take first * Regularly review the assessment process and the overall risk strategy to keep pace with new threats and changes in emergency communications requirements If yes, please explain how often you revisit your assessment process and strategy, and give one example of a recent change you made based on those results. (Example: “We reprioritized our network monitoring tools after a mid-year review in July 2024.”) | F25: Recognized need; no action taken yet. | G25: NO
B27: 2. Identity, Authentication & Access Management
C28: A. Access Control Governance & Management
A29: 2A-1 | D29: 1. | E29: Does your organization have a formal governance group and approved policies that define who can create, change, or deactivate each type of account – user, administrative, service, and cloud – across all public safety systems? If yes, please name the governance body and explain where these policies are documented. (Example: “Our Identity Steering Committee owns the policy in our Security Manual, updated annually.") | F29: Partially implemented; improvements underway. | G29: IN PROGRESS
A30: 2A-2 | D30: 2. | E30: Are job roles, functions, and data classification levels officially documented, and do you regularly review granted permissions to make sure everyone has only the minimum access required (principle of least privilege)? If yes, please describe your review schedule and who conducts it. (Example: “We run quarterly access reports; managers verify roles in our IAM tool.”) | F30: Operational and tested. | G30: YES
A31: 2A-3 | D31: 3. | E31: Do your written policies require: * Strong authentication methods (e.g., complex passwords, hardware tokens, digital certificates, or biometrics) * A clear, auditable process for issuing, storing, and revoking credentials If yes, please list which authentication methods you use and how you track the full credential lifecycle. (Example: “We enforce 12-character passwords, issue YubiKeys for admin accounts, and record revocations in our ticketing system.”) | F31: Active effort in progress. | G31: IN PROGRESS
A32: 2A-4 | D32: 4. | E32: Do you perform account reviews and disable inactive or unnecessary accounts on a set schedule (e.g., every 30, 60, or 90 days), with clear assignment of responsibility for this task? If yes, please specify your schedule and the roles responsible for reviewing and deactivating accounts. (Example: “Every 60 days, IT Support runs an inactivity report, and the Security Manager approves deactivations.”) | F32: Being addressed through current initiatives. | G32: IN PROGRESS
A33: 2A-5 | D33: 5. | E33: Do your policies control remote or vendor/partner access by specifying: * Who is allowed to connect * Under what conditions (e.g., approved devices, time windows) * What monitoring or encryption is required If yes, please briefly outline these conditions and controls. (Example: “Remote logins require VPN with MFA; third-party sessions are logged and reviewed weekly.”) | F33: Absence acknowledged; not yet prioritized. | G33: NO
A34: 2A-6 | D34: 6. | E34: Do you have dedicated policies for service-based and cloud-based accounts that define: * Who “owns” each account * Its purpose and lifespan * What specific, limited privileges it needs * The method and frequency for reviewing these accounts If yes, please point to those policies and describe your review process. (Example: “Our Cloud Access Policy in Confluence; we audit service accounts monthly.”) | F34: Control is missing; flagged for remediation. | G34: NO
C36: B. Account & Credential Lifecycle Management
A37: 2B-1 | D37: 1. | E37: Do you have formal, written procedures – aligned with HR and operational teams – for how every account (user, remote, guest, temporary) is requested, approved, created, changed, and disabled? If yes, please say where these procedures are stored and how you keep them up to date. (Example: “Procedures are in our HR policy manual and IT operations guide; they’re reviewed annually by HR and IT leads.”) | F37: Implementation underway; on track. | G37: IN PROGRESS
A38: 2B-2 | D38: 2. | E38: Do you regularly review and adjust account permissions – especially upon change in an individual’s job role or their departure – to ensure each account has only the necessary access? If yes, please describe your review process and who is responsible. (Example: “Managers submit role change notices monthly; IT removes unneeded rights within 24 hours of notice.”) | F38: Configured and enforced. | G38: YES
A39: 2B-3 | D39: 3. | E39: Do your policies require: * Strong password rules (complexity, length) * Use of tokens or certificates where appropriate * Automated enforcement of these rules * Prompt rotation or revocation of credentials when compromised or upon personnel change If yes, please list the methods in place and how you track them. (Example: “Passwords must be 12+ characters and rotate every 90 days; admin accounts use YubiKeys; all revocations are logged in our ticketing system.”) | F39: Partially configured; finishing remaining steps. | G39: IN PROGRESS
A40: 2B-4 | D40: 4. | E40: Do you have a process for managing service and application accounts that includes: * Managing an up-to-date inventory? * Assigning each a unique identifier and granting only minimal required rights? * Monitoring or rotating their credentials on a regular schedule? If yes, please explain how you track these accounts and describe your credential rotation or monitoring schedule. (Example: “We list service accounts in our IAM tool and rotate their passwords every 60 days.”) | F40: Not applicable to current practice. | G40: NO
A41: 2B-5 | D41: 5. | E41: Do you use automated tools or scripts to detect accounts that haven’t been used for a defined period and automatically disable them on a set schedule? If yes, please describe the automation and schedule. (Example: “Accounts idle for 45 days are automatically disabled by our identity platform.”) | F41: Not yet implemented. | G41: NO
C43: C. Authentication & Credential Governance
A44: 2C-1 | D44: 1. | E44: Before granting any access, do you: * Verify each person’s identity using a documented process * Issue unique credentials for every user * Manage and document any cross-system trusts (certificates, SAML federation, etc.) If yes, please describe your identity verification steps and how you track trusted system relationships. (Example: “We check government ID and HR records before account creation; all certificate-based trusts are logged in our CMDB.”) | F44: Active and monitored. | G44: YES
A45: 2C-2 | D45: 2. | E45: Do your login screens and rules ensure that: * Error messages are vague enough to avoid revealing valid usernames * Accounts lock out or throttle after a set number of failed attempts * Failed logins and other anomalies are logged and monitored * Default vendor-supplied credentials are disabled before any system goes live If yes, please describe your lockout thresholds, logging practices, and how you disable defaults. (Example: “After 5 failed attempts, accounts lock for 15 minutes; all failures flow into SIEM alerts; we run a deployment script that removes default admin/password pairs.”) | F45: Completed and maintained. | G45: YES
A46: 2C-3 | D46: 3. | E46: Are there documented rules that specify: * Password complexity and minimum length * How often passwords must be changed * Secure storage protections (for example, hashing, vaulting) * Bans on weak, reused, or shared passwords If yes, please summarize your complexity and rotation requirements as well as technical enforcement controls. (Example: “Passwords must be ≥12 characters with letters, numbers, and symbols; rotated every 90 days; all hashes stored in our hardened vault.”) | F46: Implemented and documented. | G46: YES
...

Sheet Full Score Table
D2: # of Questions | E2: Not Applicable | F2: Unknown | G2: No (0) | H2: Planned (1) | I2: In Progress (2) | J2: Yes (3) | K2: Total | L2: out of | M2: Possible
C3: Overall Total | D3: 198 | E3: =N(E8)+N(E15)+N(E19)+N(E26)+N(E31)+N(E35)+N(E40)+N(E44)+N(E49)+N(E55)+N(E60)+N(E63)+N(E67) -> 9 | F3: =N(F8)+N(F15)+N(F19)+N(F26)+N(F31)+N(F35)+N(F40)+N(F44)+N(F49)+N(F55)+N(F60)+N(F63)+N(F67) -> 7 | G3: =N(G8)+N(G15)+N(G19)+N(G26)+N(G31)+N(G35)+N(G40)+N(G44)+N(G49)+N(G55)+N(G60)+N(G63)+N(G67) -> 72 | H3: =N(H8)+N(H15)+N(H19)+N(H26)+N(H31)+N(H35)+N(H40)+N(H44)+N(H49)+N(H55)+N(H60)+N(H63)+N(H67) -> 15 | I3: =N(I8)+N(I15)+N(I19)+N(I26)+N(I31)+N(I35)+N(I40)+N(I44)+N(I49)+N(I55)+N(I60)+N(I63)+N(I67) -> 55 | J3: =N(J8)+N(J15)+N(J19)+N(J26)+N(J31)+N(J35)+N(J40)+N(J44)+N(J49)+N(J55)+N(J60)+N(J63)+N(J67) -> 40 | K3: =N(H3)+(N(I3)*2)+(N(J3)*3) -> 245 | L3: of | M3: =(SUM(F3:J3)*3) -> 567
B4: Governance, Risk & Strategy | C4: Executive Leadership & Resource Allocation | D4: 3 | E4: =_xlfn.LET(_xlpm.na,COUNTIF('Question Set'!$G$4:$G$6,"Not Applicable"),IF(_xlpm.na=0,"-",_xlpm.na)) -> - | F4: =_xlfn.LET(_xlpm.u,COUNTIF('Question Set'!$G$4:$G$6,"Unknown"),IF(_xlpm.u=0,"-",_xlpm.u)) -> - | G4: =_xlfn.LET(_xlpm.n,COUNTIF('Question Set'!$G$4:$G$6,"No"),IF(_xlpm.n=0,"-",_xlpm.n)) -> - | H4: =_xlfn.LET(_xlpm.pl,COUNTIF('Question Set'!$G$4:$G$6,"Planned"),IF(_xlpm.pl=0,"-",_xlpm.pl)) -> 1 | I4: =_xlfn.LET(_xlpm.ip,COUNTIF('Question Set'!$G$4:$G$6,"In Progress"),IF(_xlpm.ip=0,"-",_xlpm.ip)) -> - | J4: =_xlfn.LET(_xlpm.y,COUNTIF('Question Set'!$G$4:$G$6,"Yes"),IF(_xlpm.y=0,"-",_xlpm.y)) -> 2 | K4: =N(H4)+(N(I4)*2)+(N(J4)*3) -> 7 | L4: of | M4: =(SUM(F4:J4)*3) -> 9
C5: Policy & Asset Inventory Management | D5: 3 | E5: =_xlfn.LET(_xlpm.na,COUNTIF('Question Set'!$G$9:$G$11,"Not Applicable"),IF(_xlpm.na=0,"-",_xlpm.na)) -> - | F5: =_xlfn.LET(_xlpm.u,COUNTIF('Question Set'!$G$9:$G$11,"Unknown"),IF(_xlpm.u=0,"-",_xlpm.u)) -> - | G5: =_xlfn.LET(_xlpm.n,COUNTIF('Question Set'!$G$9:$G$11,"No"),IF(_xlpm.n=0,"-",_xlpm.n)) -> 2 | H5: =_xlfn.LET(_xlpm.pl,COUNTIF('Question Set'!$G$9:$G$11,"Planned"),IF(_xlpm.pl=0,"-",_xlpm.pl)) -> - | I5: =_xlfn.LET(_xlpm.ip,COUNTIF('Question Set'!$G$9:$G$11,"In Progress"),IF(_xlpm.ip=0,"-",_xlpm.ip)) -> - | J5: =_xlfn.LET(_xlpm.y,COUNTIF('Question Set'!$G$9:$G$11,"Yes"),IF(_xlpm.y=0,"-",_xlpm.y)) -> 1 | K5: =N(H5)+(N(I5)*2)+(N(J5)*3) -> 3 | L5: of | M5: =(SUM(F5:J5)*3) -> 9
C6: Role Definition & Governance Oversight | D6: 5 | E6: =_xlfn.LET(_xlpm.na,COUNTIF('Question Set'!$G$14:$G$18,"Not Applicable"),IF(_xlpm.na=0,"-",_xlpm.na)) -> - | F6: =_xlfn.LET(_xlpm.u,COUNTIF('Question Set'!$G$14:$G$18,"Unknown"),IF(_xlpm.u=0,"-",_xlpm.u)) -> - | G6: =_xlfn.LET(_xlpm.n,COUNTIF('Question Set'!$G$14:$G$18,"No"),IF(_xlpm.n=0,"-",_xlpm.n)) -> 1 | H6: =_xlfn.LET(_xlpm.pl,COUNTIF('Question Set'!$G$14:$G$18,"Planned"),IF(_xlpm.pl=0,"-",_xlpm.pl)) -> - | I6: =_xlfn.LET(_xlpm.ip,COUNTIF('Question Set'!$G$14:$G$18,"In Progress"),IF(_xlpm.ip=0,"-",_xlpm.ip)) -> 1 | J6: =_xlfn.LET(_xlpm.y,COUNTIF('Question Set'!$G$14:$G$18,"Yes"),IF(_xlpm.y=0,"-",_xlpm.y)) -> 3 | K6: =N(H6)+(N(I6)*2)+(N(J6)*3) -> 11 | L6: of | M6: =(SUM(F6:J6)*3) -> 15
C7: Risk Assessment & Management Strategy | D7: 5 | E7: =_xlfn.LET(_xlpm.na,COUNTIF('Question Set'!$G$21:$G$25,"Not Applicable"),IF(_xlpm.na=0,"-",_xlpm.na)) -> - | F7: =_xlfn.LET(_xlpm.u,COUNTIF('Question Set'!$G$21:$G$25,"Unknown"),IF(_xlpm.u=0,"-",_xlpm.u)) -> - | G7: =_xlfn.LET(_xlpm.n,COUNTIF('Question Set'!$G$21:$G$25,"No"),IF(_xlpm.n=0,"-",_xlpm.n)) -> 4 | H7: =_xlfn.LET(_xlpm.pl,COUNTIF('Question Set'!$G$21:$G$25,"Planned"),IF(_xlpm.pl=0,"-",_xlpm.pl)) -> - | I7: =_xlfn.LET(_xlpm.ip,COUNTIF('Question Set'!$G$21:$G$25,"In Progress"),IF(_xlpm.ip=0,"-",_xlpm.ip)) -> 1 | J7: =_xlfn.LET(_xlpm.y,COUNTIF('Question Set'!$G$21:$G$25,"Yes"),IF(_xlpm.y=0,"-",_xlpm.y)) -> - | K7: =N(H7)+(N(I7)*2)+(N(J7)*3) -> 2 | L7: of | M7: =(SUM(F7:J7)*3) -> 15
C8: Domain Total | D8: =SUM(D4:D7) -> 16 | E8: =_xlfn.LET(_xlpm.x,(SUM(E4:E7)),IF(_xlpm.x=0,"-",_xlpm.x)) -> - | F8: =_xlfn.LET(_xlpm.x,(SUM(F4:F7)),IF(_xlpm.x=0,"-",_xlpm.x)) -> - | G8: =_xlfn.LET(_xlpm.x,(SUM(G4:G7)),IF(_xlpm.x=0,"-",_xlpm.x)) -> 7 | H8: =_xlfn.LET(_xlpm.x,(SUM(H4:H7)),IF(_xlpm.x=0,"-",_xlpm.x)) -> 1 | I8: =_xlfn.LET(_xlpm.x,(SUM(I4:I7)),IF(_xlpm.x=0,"-",_xlpm.x)) -> 2 | J8: =_xlfn.LET(_xlpm.x,(SUM(J4:J7)),IF(_xlpm.x=0,"-",_xlpm.x)) -> 6 | K8: =N(H8)+(N(I8)*2)+(N(J8)*3) -> 23 | L8: of | M8: =(SUM(F8:J8)*3) -> 48
B9: Identity, Authentication & Access Management | C9: Access Control Governance & Management | D9: 6 | E9: =_xlfn.LET(_xlpm.na,COUNTIF('Question Set'!$G$29:$G$34,"Not Applicable"),IF(_xlpm.na=0,"-",_xlpm.na)) -> - | F9: =_xlfn.LET(_xlpm.u,COUNTIF('Question Set'!$G$29:$G$34,"Unknown"),IF(_xlpm.u=0,"-",_xlpm.u)) -> - | G9: =_xlfn.LET(_xlpm.n,COUNTIF('Question Set'!$G$29:$G$34,"No"),IF(_xlpm.n=0,"-",_xlpm.n)) -> 2 | H9: =_xlfn.LET(_xlpm.pl,COUNTIF('Question Set'!$G$29:$G$34,"Planned"),IF(_xlpm.pl=0,"-",_xlpm.pl)) -> - | I9: =_xlfn.LET(_xlpm.ip,COUNTIF('Question Set'!$G$29:$G$34,"In Progress"),IF(_xlpm.ip=0,"-",_xlpm.ip)) -> 3 | J9: =_xlfn.LET(_xlpm.y,COUNTIF('Question Set'!$G$29:$G$34,"Yes"),IF(_xlpm.y=0,"-",_xlpm.y)) -> 1 | K9: =N(H9)+(N(I9)*2)+(N(J9)*3) -> 9 | L9: of | M9: =(SUM(F9:J9)*3) -> 18
C10: Account & Credential Lifecycle Management | D10: 5 | E10: =_xlfn.LET(_xlpm.na,COUNTIF('Question Set'!$G$37:$G$41,"Not Applicable"),IF(_xlpm.na=0,"-",_xlpm.na)) -> - | F10: =_xlfn.LET(_xlpm.u,COUNTIF('Question Set'!$G$37:$G$41,"Unknown"),IF(_xlpm.u=0,"-",_xlpm.u)) -> - | G10: =_xlfn.LET(_xlpm.n,COUNTIF('Question Set'!$G$37:$G$41,"No"),IF(_xlpm.n=0,"-",_xlpm.n)) -> 2 | H10: =_xlfn.LET(_xlpm.pl,COUNTIF('Question Set'!$G$37:$G$41,"Planned"),IF(_xlpm.pl=0,"-",_xlpm.pl)) -> - | I10: =_xlfn.LET(_xlpm.ip,COUNTIF('Question Set'!$G$37:$G$41,"In Progress"),IF(_xlpm.ip=0,"-",_xlpm.ip)) -> 2 | J10: =_xlfn.LET(_xlpm.y,COUNTIF('Question Set'!$G$37:$G$41,"Yes"),IF(_xlpm.y=0,"-",_xlpm.y)) -> 1 | K10: =N(H10)+(N(I10)*2)+(N(J10)*3) -> 7 | L10: of | M10: =(SUM(F10:J10)*3) -> 15
C11: Authentication & Credential Governance | D11: 5 | E11: =_xlfn.LET(_xlpm.na,COUNTIF('Question Set'!$G$44:$G$48,"Not Applicable"),IF(_xlpm.na=0,"-",_xlpm.na)) -> - | F11: =_xlfn.LET(_xlpm.u,COUNTIF('Question Set'!$G$44:$G$48,"Unknown"),IF(_xlpm.u=0,"-",_xlpm.u)) -> - | G11: =_xlfn.LET(_xlpm.n,COUNTIF('Question Set'!$G$44:$G$48,"No"),IF(_xlpm.n=0,"-",_xlpm.n)) -> 1 | H11: =_xlfn.LET(_xlpm.pl,COUNTIF('Question Set'!$G$44:$G$48,"Planned"),IF(_xlpm.pl=0,"-",_xlpm.pl)) -> - | I11: =_xlfn.LET(_xlpm.ip,COUNTIF('Question Set'!$G$44:$G$48,"In Progress"),IF(_xlpm.ip=0,"-",_xlpm.ip)) -> - | J11: =_xlfn.LET(_xlpm.y,COUNTIF('Question Set'!$G$44:$G$48,"Yes"),IF(_xlpm.y=0,"-",_xlpm.y)) -> 4 | K11: =N(H11)+(N(I11)*2)+(N(J11)*3) -> 12 | L11: of | M11: =(SUM(F11:J11)*3) -> 15
C12: Authorization & Least Privilege Enforcement | D12: 4 | E12: =_xlfn.LET(_xlpm.na,COUNTIF('Question Set'!$G$51:$G$54,"Not Applicable"),IF(_xlpm.na=0,"-",_xlpm.na)) -> - | F12: =_xlfn.LET(_xlpm.u,COUNTIF('Question Set'!$G$51:$G$54,"Unknown"),IF(_xlpm.u=0,"-",_xlpm.u)) -> - | G12: =_xlfn.LET(_xlpm.n,COUNTIF('Question Set'!$G$51:$G$54,"No"),IF(_xlpm.n=0,"-",_xlpm.n)) -> 2 | H12: =_xlfn.LET(_xlpm.pl,COUNTIF('Question Set'!$G$51:$G$54,"Planned"),IF(_xlpm.pl=0,"-",_xlpm.pl)) -> - | I12: =_xlfn.LET(_xlpm.ip,COUNTIF('Question Set'!$G$51:$G$54,"In Progress"),IF(_xlpm.ip=0,"-",_xlpm.ip)) -> 2 | J12: =_xlfn.LET(_xlpm.y,COUNTIF('Question Set'!$G$51:$G$54,"Yes"),IF(_xlpm.y=0,"-",_xlpm.y)) -> - | K12: =N(H12)+(N(I12)*2)+(N(J12)*3) -> 4 | L12: of | M12: =(SUM(F12:J12)*3) -> 12
C13: Privileged Access Governance & Monitoring | D13: 5 | E13: =_xlfn.LET(_xlpm.na,COUNTIF('Question Set'!$G$57:$G$61,"Not Applicable"),IF(_xlpm.na=0,"-",_xlpm.na)) -> - | F13: =_xlfn.LET(_xlpm.u,COUNTIF('Question Set'!$G$57:$G$61,"Unknown"),IF(_xlpm.u=0,"-",_xlpm.u)) -> 1 | G13: =_xlfn.LET(_xlpm.n,COUNTIF('Question Set'!$G$57:$G$61,"No"),IF(_xlpm.n=0,"-",_xlpm.n)) -> 1 | H13: =_xlfn.LET(_xlpm.pl,COUNTIF('Question Set'!$G$57:$G$61,"Planned"),IF(_xlpm.pl=0,"-",_xlpm.pl)) -> - | I13: =_xlfn.LET(_xlpm.ip,COUNTIF('Question Set'!$G$57:$G$61,"In Progress"),IF(_xlpm.ip=0,"-",_xlpm.ip)) -> 2 | J13: =_xlfn.LET(_xlpm.y,COUNTIF('Question Set'!$G$57:$G$61,"Yes"),IF(_xlpm.y=0,"-",_xlpm.y)) -> 1 | K13: =N(H13)+(N(I13)*2)+(N(J13)*3) -> 7 | L13: of | M13: =(SUM(F13:J13)*3) -> 15
C14: Session Management & Monitoring | D14: 5 | E14: =_xlfn.LET(_xlpm.na,COUNTIF('Question Set'!$G$64:$G$68,"Not Applicable"),IF(_xlpm.na=0,"-",_xlpm.na)) -> - | F14: =_xlfn.LET(_xlpm.u,COUNTIF('Question Set'!$G$64:$G$68,"Unknown"),IF(_xlpm.u=0,"-",_xlpm.u)) -> - | G14: =_xlfn.LET(_xlpm.n,COUNTIF('Question Set'!$G$64:$G$68,"No"),IF(_xlpm.n=0,"-",_xlpm.n)) -> 1 | H14: =_xlfn.LET(_xlpm.pl,COUNTIF('Question Set'!$G$64:$G$68,"Planned"),IF(_xlpm.pl=0,"-",_xlpm.pl)) -> - | I14: =_xlfn.LET(_xlpm.ip,COUNTIF('Question Set'!$G$64:$G$68,"In Progress"),IF(_xlpm.ip=0,"-",_xlpm.ip)) -> 4 | J14: =_xlfn.LET(_xlpm.y,COUNTIF('Question Set'!$G$64:$G$68,"Yes"),IF(_xlpm.y=0,"-",_xlpm.y)) -> - | K14: =N(H14)+(N(I14)*2)+(N(J14)*3) -> 8 | L14: of | M14: =(SUM(F14:J14)*3) -> 15
C15: Domain Total | D15: =SUM(D9:D14) -> 30 | E15: =_xlfn.LET(_xlpm.x,(SUM(E9:E14)),IF(_xlpm.x=0,"-",_xlpm.x)) -> - | F15: =_xlfn.LET(_xlpm.x,(SUM(F9:F14)),IF(_xlpm.x=0,"-",_xlpm.x)) -> 1 | G15: =_xlfn.LET(_xlpm.x,(SUM(G9:G14)),IF(_xlpm.x=0,"-",_xlpm.x)) -> 9 | H15: =_xlfn.LET(_xlpm.x,(SUM(H9:H14)),IF(_xlpm.x=0,"-",_xlpm.x)) -> - | I15: =_xlfn.LET(_xlpm.x,(SUM(I9:I14)),IF(_xlpm.x=0,"-",_xlpm.x)) -> 13 | J15: =_xlfn.LET(_xlpm.x,(SUM(J9:J14)),IF(_xlpm.x=0,"-",_xlpm.x)) -> 7 | K15: =N(H15)+(N(I15)*2)+(N(J15)*3) -> 47 | L15: of | M15: =(SUM(F15:J15)*3) -> 90
B16: Data Security & Lifecycle Management | C16: Data Classification & Labeling | D16: 3 | E16: =_xlfn.LET(_xlpm.na,COUNTIF('Question Set'!$G$72:$G$74,"Not Applicable"),IF(_xlpm.na=0,"-",_xlpm.na)) -> - | F16: =_xlfn.LET(_xlpm.u,COUNTIF('Question Set'!$G$72:$G$74,"Unknown"),IF(_xlpm.u=0,"-",_xlpm.u)) -> - | G16: =_xlfn.LET(_xlpm.n,COUNTIF('Question Set'!$G$72:$G$74,"No"),IF(_xlpm.n=0,"-",_xlpm.n)) -> 2 | H16: =_xlfn.LET(_xlpm.pl,COUNTIF('Question Set'!$G$72:$G$74,"Planned"),IF(_xlpm.pl=0,"-",_xlpm.pl)) -> - | I16: =_xlfn.LET(_xlpm.ip,COUNTIF('Question Set'!$G$72:$G$74,"In Progress"),IF(_xlpm.ip=0,"-",_xlpm.ip)) -> - | J16: =_xlfn.LET(_xlpm.y,COUNTIF('Question Set'!$G$72:$G$74,"Yes"),IF(_xlpm.y=0,"-",_xlpm.y)) -> 1 | K16: =N(H16)+(N(I16)*2)+(N(J16)*3) -> 3 | L16: of | M16: =(SUM(F16:J16)*3) -> 9
C17: Data Protection & Lifecycle Management | D17: 6 | E17: =_xlfn.LET(_xlpm.na,COUNTIF('Question Set'!$G$77:$G$82,"Not Applicable"),IF(_xlpm.na=0,"-",_xlpm.na)) -> - | F17: =_xlfn.LET(_xlpm.u,COUNTIF('Question Set'!$G$77:$G$82,"Unknown"),IF(_xlpm.u=0,"-",_xlpm.u)) -> - | G17: =_xlfn.LET(_xlpm.n,COUNTIF('Question Set'!$G$77:$G$82,"No"),IF(_xlpm.n=0,"-",_xlpm.n)) -> 1 | H17: =_xlfn.LET(_xlpm.pl,COUNTIF('Question Set'!$G$77:$G$82,"Planned"),IF(_xlpm.pl=0,"-",_xlpm.pl)) -> 2 | I17: =_xlfn.LET(_xlpm.ip,COUNTIF('Question Set'!$G$77:$G$82,"In Progress"),IF(_xlpm.ip=0,"-",_xlpm.ip)) -> 3 | J17: =_xlfn.LET(_xlpm.y,COUNTIF('Question Set'!$G$77:$G$82,"Yes"),IF(_xlpm.y=0,"-",_xlpm.y)) -> - | K17: =N(H17)+(N(I17)*2)+(N(J17)*3) -> 8 | L17: of | M17: =(SUM(F17:J17)*3) -> 18
C18: Data Access Monitoring & Disclosure Management | D18: 3 | E18: =_xlfn.LET(_xlpm.na,COUNTIF('Question Set'!$G$85:$G$87,"Not Applicable"),IF(_xlpm.na=0,"-",_xlpm.na)) -> - | F18: =_xlfn.LET(_xlpm.u,COUNTIF('Question Set'!$G$85:$G$87,"Unknown"),IF(_xlpm.u=0,"-",_xlpm.u)) -> - | G18: =_xlfn.LET(_xlpm.n,COUNTIF('Question Set'!$G$85:$G$87,"No"),IF(_xlpm.n=0,"-",_xlpm.n)) -> - | H18: =_xlfn.LET(_xlpm.pl,COUNTIF('Question Set'!$G$85:$G$87,"Planned"),IF(_xlpm.pl=0,"-",_xlpm.pl)) -> - | I18: =_xlfn.LET(_xlpm.ip,COUNTIF('Question Set'!$G$85:$G$87,"In Progress"),IF(_xlpm.ip=0,"-",_xlpm.ip)) -> 2 | J18: =_xlfn.LET(_xlpm.y,COUNTIF('Question Set'!$G$85:$G$87,"Yes"),IF(_xlpm.y=0,"-",_xlpm.y)) -> 1 | K18: =N(H18)+(N(I18)*2)+(N(J18)*3) -> 7 | L18: of | M18: =(SUM(F18:J18)*3) -> 9
C19: Domain Total | D19: =SUM(D16:D18) -> 12 | E19: =_xlfn.LET(_xlpm.x,(SUM(E16:E18)),IF(_xlpm.x=0,"-",_xlpm.x)) -> - | F19: =_xlfn.LET(_xlpm.x,(SUM(F16:F18)),IF(_xlpm.x=0,"-",_xlpm.x)) -> - | G19: =_xlfn.LET(_xlpm.x,(SUM(G16:G18)),IF(_xlpm.x=0,"-",_xlpm.x)) -> 3 | H19: =_xlfn.LET(_xlpm.x,(SUM(H16:H18)),IF(_xlpm.x=0,"-",_xlpm.x)) -> 2 | I19: =_xlfn.LET(_xlpm.x,(SUM(I16:I18)),IF(_xlpm.x=0,"-",_xlpm.x)) -> 5 | J19: =_xlfn.LET(_xlpm.x,(SUM(J16:J18)),IF(_xlpm.x=0,"-",_xlpm.x)) -> 2 | K19: =N(H19)+(N(I19)*2)+(N(J19)*3) -> 18 | L19: of | M19: =(SUM(F19:J19)*3) -> 36
B20: Network & Communications Governance | C20: Network Infrastructure & Boundary Controls | D20: 5 | E20: =_xlfn.LET(_xlpm.na,COUNTIF('Question Set'!$G$91:$G$95,"Not Applicable"),IF(_xlpm.na=0,"-",_xlpm.na)) -> - | F20: =_xlfn.LET(_xlpm.u,COUNTIF('Question Set'!$G$91:$G$95,"Unknown"),IF(_xlpm.u=0,"-",_xlpm.u)) -> - | G20: =_xlfn.LET(_xlpm.n,COUNTIF('Question Set'!$G$91:$G$95,"No"),IF(_xlpm.n=0,"-",_xlpm.n)) -> - | H20: =_xlfn.LET(_xlpm.pl,COUNTIF('Question Set'!$G$91:$G$95,"Planned"),IF(_xlpm.pl=0,"-",_xlpm.pl)) -> - | I20: =_xlfn.LET(_xlpm.ip,COUNTIF('Question Set'!$G$91:$G$95,"In Progress"),IF(_xlpm.ip=0,"-",_xlpm.ip)) -> 4 | J20: =_xlfn.LET(_xlpm.y,COUNTIF('Question Set'!$G$91:$G$95,"Yes"),IF(_xlpm.y=0,"-",_xlpm.y)) -> 1 | K20: =N(H20)+(N(I20)*2)+(N(J20)*3) -> 11 | L20: of | M20: =(SUM(F20:J20)*3) -> 15
C21: Network Traffic & Threat Controls | D21: 5 | E21: =_xlfn.LET(_xlpm.na,COUNTIF('Question Set'!$G$98:$G$102,"Not Applicable"),IF(_xlpm.na=0,"-",_xlpm.na)) -> - | F21: =_xlfn.LET(_xlpm.u,COUNTIF('Question Set'!$G$98:$G$102,"Unknown"),IF(_xlpm.u=0,"-",_xlpm.u)) -> - | G21: =_xlfn.LET(_xlpm.n,COUNTIF('Question Set'!$G$98:$G$102,"No"),IF(_xlpm.n=0,"-",_xlpm.n)) -> 1 | H21: =_xlfn.LET(_xlpm.pl,COUNTIF('Question Set'!$G$98:$G$102,"Planned"),IF(_xlpm.pl=0,"-",_xlpm.pl)) -> 2 | I21: =_xlfn.LET(_xlpm.ip,COUNTIF('Question Set'!$G$98:$G$102,"In Progress"),IF(_xlpm.ip=0,"-",_xlpm.ip)) -> 2 | J21: =_xlfn.LET(_xlpm.y,COUNTIF('Question Set'!$G$98:$G$102,"Yes"),IF(_xlpm.y=0,"-",_xlpm.y)) -> - | K21: =N(H21)+(N(I21)*2)+(N(J21)*3) -> 6 | L21: of | M21: =(SUM(F21:J21)*3) -> 15
C22: DNS Governance & Security Controls | D22: 6 | E22: =_xlfn.LET(_xlpm.na,COUNTIF('Question Set'!$G$105:$G$110,"Not Applicable"),IF(_xlpm.na=0,"-",_xlpm.na)) -> - | F22: =_xlfn.LET(_xlpm.u,COUNTIF('Question Set'!$G$105:$G$110,"Unknown"),IF(_xlpm.u=0,"-",_xlpm.u)) -> 1 | G22: =_xlfn.LET(_xlpm.n,COUNTIF('Question Set'!$G$105:$G$110,"No"),IF(_xlpm.n=0,"-",_xlpm.n)) -> 4 | H22: =_xlfn.LET(_xlpm.pl,COUNTIF('Question Set'!$G$105:$G$110,"Planned"),IF(_xlpm.pl=0,"-",_xlpm.pl)) -> - | I22: =_xlfn.LET(_xlpm.ip,COUNTIF('Question Set'!$G$105:$G$110,"In Progress"),IF(_xlpm.ip=0,"-",_xlpm.ip)) -> 1 | J22: =_xlfn.LET(_xlpm.y,COUNTIF('Question Set'!$G$105:$G$110,"Yes"),IF(_xlpm.y=0,"-",_xlpm.y)) -> - | K22: =N(H22)+(N(I22)*2)+(N(J22)*3) -> 2 | L22: of | M22: =(SUM(F22:J22)*3) -> 18
C23: Email System Security & Threat Protection | D23: 4 | E23: =_xlfn.LET(_xlpm.na,COUNTIF('Question Set'!$G$113:$G$116,"Not Applicable"),IF(_xlpm.na=0,"-",_xlpm.na)) -> 1 | F23: =_xlfn.LET(_xlpm.u,COUNTIF('Question Set'!$G$113:$G$116,"Unknown"),IF(_xlpm.u=0,"-",_xlpm.u)) -> - | G23: =_xlfn.LET(_xlpm.n,COUNTIF('Question Set'!$G$113:$G$116,"No"),IF(_xlpm.n=0,"-",_xlpm.n)) -> - | H23: =_xlfn.LET(_xlpm.pl,COUNTIF('Question Set'!$G$113:$G$116,"Planned"),IF(_xlpm.pl=0,"-",_xlpm.pl)) -> - | I23: =_xlfn.LET(_xlpm.ip,COUNTIF('Question Set'!$G$113:$G$116,"In Progress"),IF(_xlpm.ip=0,"-",_xlpm.ip)) -> - | J23: =_xlfn.LET(_xlpm.y,COUNTIF('Question Set'!$G$113:$G$116,"Yes"),IF(_xlpm.y=0,"-",_xlpm.y)) -> 3 | K23: =N(H23)+(N(I23)*2)+(N(J23)*3) -> 9 | L23: of | M23: =(SUM(F23:J23)*3) -> 9
C24: Wireless & Cellular Communications Security | D24: 5 | E24: =_xlfn.LET(_xlpm.na,COUNTIF('Question Set'!$G$119:$G$123,"Not Applicable"),IF(_xlpm.na=0,"-",_xlpm.na)) -> 1 | F24: =_xlfn.LET(_xlpm.u,COUNTIF('Question Set'!$G$119:$G$123,"Unknown"),IF(_xlpm.u=0,"-",_xlpm.u)) -> 1 | G24: =_xlfn.LET(_xlpm.n,COUNTIF('Question Set'!$G$119:$G$123,"No"),IF(_xlpm.n=0,"-",_xlpm.n)) -> 1 | H24: =_xlfn.LET(_xlpm.pl,COUNTIF('Question Set'!$G$119:$G$123,"Planned"),IF(_xlpm.pl=0,"-",_xlpm.pl)) -> 1 | I24: =_xlfn.LET(_xlpm.ip,COUNTIF('Question Set'!$G$119:$G$123,"In Progress"),IF(_xlpm.ip=0,"-",_xlpm.ip)) -> 1 | J24: =_xlfn.LET(_xlpm.y,COUNTIF('Question Set'!$G$119:$G$123,"Yes"),IF(_xlpm.y=0,"-",_xlpm.y)) -> - | K24: =N(H24)+(N(I24)*2)+(N(J24)*3) -> 3 | L24: of | M24: =(SUM(F24:J24)*3) -> 12
C25: Device & Remote Connectivity Controls | D25: 4 | E25: =_xlfn.LET(_xlpm.na,COUNTIF('Question Set'!$G$126:$G$129,"Not Applicable"),IF(_xlpm.na=0,"-",_xlpm.na)) -> - | F25: =_xlfn.LET(_xlpm.u,COUNTIF('Question Set'!$G$126:$G$129,"Unknown"),IF(_xlpm.u=0,"-",_xlpm.u)) -> 1 | G25: =_xlfn.LET(_xlpm.n,COUNTIF('Question Set'!$G$126:$G$129,"No"),IF(_xlpm.n=0,"-",_xlpm.n)) -> 2 | H25: =_xlfn.LET(_xlpm.pl,COUNTIF('Question Set'!$G$126:$G$129,"Planned"),IF(_xlpm.pl=0,"-",_xlpm.pl)) -> - | I25: =_xlfn.LET(_xlpm.ip,COUNTIF('Question Set'!$G$126:$G$129,"In Progress"),IF(_xlpm.ip=0,"-",_xlpm.ip)) -> 1 | J25: =_xlfn.LET(_xlpm.y,COUNTIF('Question Set'!$G$126:$G$129,"Yes"),IF(_xlpm.y=0,"-",_xlpm.y)) -> - | K25: =N(H25)+(N(I25)*2)+(N(J25)*3) -> 2 | L25: of | M25: =(SUM(F25:J25)*3) -> 12
C26: Domain Total | D26: =SUM(D20:D25) -> 29 | E26: =_xlfn.LET(_xlpm.x,SUM(E20:E25),IF(_xlpm.x=0,"-",_xlpm.x)) -> 2 | F26: =_xlfn.LET(_xlpm.x,SUM(F20:F25),IF(_xlpm.x=0,"-",_xlpm.x)) -> 3 | G26: =_xlfn.LET(_xlpm.x,SUM(G20:G25),IF(_xlpm.x=0,"-",_xlpm.x)) -> 8 | H26: =_xlfn.LET(_xlpm.x,SUM(H20:H25),IF(_xlpm.x=0,"-",_xlpm.x)) -> 3 | I26: =_xlfn.LET(_xlpm.x,SUM(I20:I25),IF(_xlpm.x=0,"-",_xlpm.x)) -> 9 | J26: =_xlfn.LET(_xlpm.x,SUM(J20:J25),IF(_xlpm.x=0,"-",_xlpm.x)) -> 4 | K26: =N(H26)+(N(I26)*2)+(N(J26)*3) -> 33 | L26: of | M26: =(SUM(F26:J26)*3) -> 81
B27: Endpoint Security & Configuration Management | C27: Baseline Configuration & Asset Management | D27: 5 | E27: =_xlfn.LET(_xlpm.na,COUNTIF('Question Set'!$G$133:$G$137,"Not Applicable"),IF(_xlpm.na=0,"-",_xlpm.na)) -> - | F27: =_xlfn.LET(_xlpm.u,COUNTIF('Question Set'!$G$133:$G$137,"Unknown"),IF(_xlpm.u=0,"-",_xlpm.u)) -> - | G27: =_xlfn.LET(_xlpm.n,COUNTIF('Question Set'!$G$133:$G$137,"No"),IF(_xlpm.n=0,"-",_xlpm.n)) -> 2 | H27: =_xlfn.LET(_xlpm.pl,COUNTIF('Question Set'!$G$133:$G$137,"Planned"),IF(_xlpm.pl=0,"-",_xlpm.pl)) -> 1 | I27: =_xlfn.LET(_xlpm.ip,COUNTIF('Question Set'!$G$133:$G$137,"In Progress"),IF(_xlpm.ip=0,"-",_xlpm.ip)) -> 1 | J27: =_xlfn.LET(_xlpm.y,COUNTIF('Question Set'!$G$133:$G$137,"Yes"),IF(_xlpm.y=0,"-",_xlpm.y)) -> 1 | K27: =N(H27)+(N(I27)*2)+(N(J27)*3) -> 6 | L27: of | M27: =(SUM(F27:J27)*3) -> 15
C28: Service & Endpoint Hardening Controls | D28: 5 | E28: =_xlfn.LET(_xlpm.na,COUNTIF('Question Set'!$G$140:$G$144,"Not Applicable"),IF(_xlpm.na=0,"-",_xlpm.na)) -> 1 | F28: =_xlfn.LET(_xlpm.u,COUNTIF('Question Set'!$G$140:$G$144,"Unknown"),IF(_xlpm.u=0,"-",_xlpm.u)) -> - | G28: =_xlfn.LET(_xlpm.n,COUNTIF('Question Set'!$G$140:$G$144,"No"),IF(_xlpm.n=0,"-",_xlpm.n)) -> 2 | H28: =_xlfn.LET(_xlpm.pl,COUNTIF('Question Set'!$G$140:$G$144,"Planned"),IF(_xlpm.pl=0,"-",_xlpm.pl)) -> - | I28: =_xlfn.LET(_xlpm.ip,COUNTIF('Question Set'!$G$140:$G$144,"In Progress"),IF(_xlpm.ip=0,"-",_xlpm.ip)) -> - | J28: =_xlfn.LET(_xlpm.y,COUNTIF('Question Set'!$G$140:$G$144,"Yes"),IF(_xlpm.y=0,"-",_xlpm.y)) -> 2 | K28: =N(H28)+(N(I28)*2)+(N(J28)*3) -> 6 | L28: of | M28: =(SUM(F28:J28)*3) -> 12
C29: Configuration, Change & Patch Management | D29: 5 | E29: =_xlfn.LET(_xlpm.na,COUNTIF('Question Set'!$G$147:$G$151,"Not Applicable"),IF(_xlpm.na=0,"-",_xlpm.na)) -> 2 | F29: =_xlfn.LET(_xlpm.u,COUNTIF('Question Set'!$G$147:$G$151,"Unknown"),IF(_xlpm.u=0,"-",_xlpm.u)) -> - | G29: =_xlfn.LET(_xlpm.n,COUNTIF('Question Set'!$G$147:$G$151,"No"),IF(_xlpm.n=0,"-",_xlpm.n)) -> 2 | H29: =_xlfn.LET(_xlpm.pl,COUNTIF('Question Set'!$G$147:$G$151,"Planned"),IF(_xlpm.pl=0,"-",_xlpm.pl)) -> - | I29: =_xlfn.LET(_xlpm.ip,COUNTIF('Question Set'!$G$147:$G$151,"In Progress"),IF(_xlpm.ip=0,"-",_xlpm.ip)) -> - | J29: =_xlfn.LET(_xlpm.y,COUNTIF('Question Set'!$G$147:$G$151,"Yes"),IF(_xlpm.y=0,"-",_xlpm.y)) -> 1 | K29: =N(H29)+(N(I29)*2)+(N(J29)*3) -> 3 | L29: of | M29: =(SUM(F29:J29)*3) -> 9
C30: Endpoint & Remote Device Security | D30: 4 | E30: =_xlfn.LET(_xlpm.na,COUNTIF('Question Set'!$G$154:$G$157,"Not Applicable"),IF(_xlpm.na=0,"-",_xlpm.na)) -> - | F30: =_xlfn.LET(_xlpm.u,COUNTIF('Question Set'!$G$154:$G$157,"Unknown"),IF(_xlpm.u=0,"-",_xlpm.u)) -> - | G30: =_xlfn.LET(_xlpm.n,COUNTIF('Question Set'!$G$154:$G$157,"No"),IF(_xlpm.n=0,"-",_xlpm.n)) -> 2 | H30: =_xlfn.LET(_xlpm.pl,COUNTIF('Question Set'!$G$154:$G$157,"Planned"),IF(_xlpm.pl=0,"-",_xlpm.pl)) -> - | I30: =_xlfn.LET(_xlpm.ip,COUNTIF('Question Set'!$G$154:$G$157,"In Progress"),IF(_xlpm.ip=0,"-",_xlpm.ip)) -> - | J30: =_xlfn.LET(_xlpm.y,COUNTIF('Question Set'!$G$154:$G$157,"Yes"),IF(_xlpm.y=0,"-",_xlpm.y)) -> 2 | K30: =N(H30)+(N(I30)*2)+(N(J30)*3) -> 6 | L30: of | M30: =(SUM(F30:J30)*3) -> 12
C31: Domain Total | D31: =SUM(D27:D30) -> 19 | E31: =_xlfn.LET(_xlpm.x,SUM(E27:E30),IF(_xlpm.x=0,"-",_xlpm.x)) -> 3 | F31: =_xlfn.LET(_xlpm.x,SUM(F27:F30),IF(_xlpm.x=0,"-",_xlpm.x)) -> - | G31: =_xlfn.LET(_xlpm.x,SUM(G27:G30),IF(_xlpm.x=0,"-",_xlpm.x)) -> 8 | H31: =_xlfn.LET(_xlpm.x,SUM(H27:H30),IF(_xlpm.x=0,"-",_xlpm.x)) -> 1 | I31: =_xlfn.LET(_xlpm.x,SUM(I27:I30),IF(_xlpm.x=0,"-",_xlpm.x)) -> 1 | J31: =_xlfn.LET(_xlpm.x,SUM(J27:J30),IF(_xlpm.x=0,"-",_xlpm.x)) -> 6 | K31: =N(H31)+(N(I31)*2)+(N(J31)*3) -> 21 | L31: of | M31: =(SUM(F31:J31)*3) -> 48
B32: Cryptography, Encryption & Key Management Governance | C32: Encryption & Cryptography Governance | D32: 3 | E32: =_xlfn.LET(_xlpm.na,COUNTIF('Question Set'!$G$161:$G$163,"Not Applicable"),IF(_xlpm.na=0,"-",_xlpm.na)) -> - | F32: =_xlfn.LET(_xlpm.u,COUNTIF('Question Set'!$G$161:$G$163,"Unknown"),IF(_xlpm.u=0,"-",_xlpm.u)) -> 1 | G32: =_xlfn.LET(_xlpm.n,COUNTIF('Question Set'!$G$161:$G$163,"No"),IF(_xlpm.n=0,"-",_xlpm.n)) -> 2 | H32: =_xlfn.LET(_xlpm.pl,COUNTIF('Question Set'!$G$161:$G$163,"Planned"),IF(_xlpm.pl=0,"-",_xlpm.pl)) -> - | I32: =_xlfn.LET(_xlpm.ip,COUNTIF('Question Set'!$G$161:$G$163,"In Progress"),IF(_xlpm.ip=0,"-",_xlpm.ip)) -> - | J32: =_xlfn.LET(_xlpm.y,COUNTIF('Question Set'!$G$161:$G$163,"Yes"),IF(_xlpm.y=0,"-",_xlpm.y)) -> - | K32: =N(H32)+(N(I32)*2)+(N(J32)*3) -> 0 | L32: of | M32: =(SUM(F32:J32)*3) -> 9
C33: PKI & Certificate Management | D33: 3 | E33: =_xlfn.LET(_xlpm.na,COUNTIF('Question Set'!$G$166:$G$168,"Not Applicable"),IF(_xlpm.na=0,"-",_xlpm.na)) -> - | F33: =_xlfn.LET(_xlpm.u,COUNTIF('Question Set'!$G$166:$G$168,"Unknown"),IF(_xlpm.u=0,"-",_xlpm.u)) -> - | G33: =_xlfn.LET(_xlpm.n,COUNTIF('Question Set'!$G$166:$G$168,"No"),IF(_xlpm.n=0,"-",_xlpm.n)) -> 3 | H33: =_xlfn.LET(_xlpm.pl,COUNTIF('Question Set'!$G$166:$G$168,"Planned"),IF(_xlpm.pl=0,"-",_xlpm.pl)) -> - | I33: =_xlfn.LET(_xlpm.ip,COUNTIF('Question Set'!$G$166:$G$168,"In Progress"),IF(_xlpm.ip=0,"-",_xlpm.ip)) -> - | J33: =_xlfn.LET(_xlpm.y,COUNTIF('Question Set'!$G$166:$G$168,"Yes"),IF(_xlpm.y=0,"-",_xlpm.y)) -> - | K33: =N(H33)+(N(I33)*2)+(N(J33)*3) -> 0 | L33: of | M33: =(SUM(F33:J33)*3) -> 9
C34: Cryptographic Key Governance & Availability | D34: 4 | E34: =_xlfn.LET(_xlpm.na,COUNTIF('Question Set'!$G$171:$G$174,"Not Applicable"),IF(_xlpm.na=0,"-",_xlpm.na)) -> 1 | F34: =_xlfn.LET(_xlpm.u,COUNTIF('Question Set'!$G$171:$G$174,"Unknown"),IF(_xlpm.u=0,"-",_xlpm.u)) -> - | G34: =_xlfn.LET(_xlpm.n,COUNTIF('Question Set'!$G$171:$G$174,"No"),IF(_xlpm.n=0,"-",_xlpm.n)) -> 3 | H34: =_xlfn.LET(_xlpm.pl,COUNTIF('Question Set'!$G$171:$G$174,"Planned"),IF(_xlpm.pl=0,"-",_xlpm.pl)) -> - | I34: =_xlfn.LET(_xlpm.ip,COUNTIF('Question Set'!$G$171:$G$174,"In Progress"),IF(_xlpm.ip=0,"-",_xlpm.ip)) -> - | J34: =_xlfn.LET(_xlpm.y,COUNTIF('Question Set'!$G$171:$G$174,"Yes"),IF(_xlpm.y=0,"-",_xlpm.y)) -> - | K34: =N(H34)+(N(I34)*2)+(N(J34)*3) -> 0 | L34: of | M34: =(SUM(F34:J34)*3) -> 9
C35: Domain Total | D35: =SUM(D32:D34) -> 10 | E35: =_xlfn.LET(_xlpm.x,SUM(E32:E34),IF(_xlpm.x=0,"-",_xlpm.x)) -> 1 | F35: =_xlfn.LET(_xlpm.x,SUM(F32:F34),IF(_xlpm.x=0,"-",_xlpm.x)) -> 1 | G35: =_xlfn.LET(_xlpm.x,SUM(G32:G34),IF(_xlpm.x=0,"-",_xlpm.x)) -> 8 | H35: =_xlfn.LET(_xlpm.x,SUM(H32:H34),IF(_xlpm.x=0,"-",_xlpm.x)) -> - | I35: =_xlfn.LET(_xlpm.x,SUM(I32:I34),IF(_xlpm.x=0,"-",_xlpm.x)) -> - | J35: =_xlfn.LET(_xlpm.x,SUM(J32:J34),IF(_xlpm.x=0,"-",_xlpm.x)) -> - | K35: =N(H35)+(N(I35)*2)+(N(J35)*3) -> 0 | L35: of | M35: =(SUM(F35:J35)*3) -> 27
B36: Logging, Monitoring & Event Detection | C36: Logging Policy, Content & Review | D36: 4 | E36: =_xlfn.LET(_xlpm.na,COUNTIF('Question Set'!$G$178:$G$181,"Not Applicable"),IF(_xlpm.na=0,"-",_xlpm.na)) -> - | F36: =_xlfn.LET(_xlpm.u,COUNTIF('Question Set'!$G$178:$G$181,"Unknown"),IF(_xlpm.u=0,"-",_xlpm.u)) -> - | G36: =_xlfn.LET(_xlpm.n,COUNTIF('Question Set'!$G$178:$G$181,"No"),IF(_xlpm.n=0,"-",_xlpm.n)) -> 2 | H36: =_xlfn.LET(_xlpm.pl,COUNTIF('Question Set'!$G$178:$G$181,"Planned"),IF(_xlpm.pl=0,"-",_xlpm.pl)) -> - | I36: =_xlfn.LET(_xlpm.ip,COUNTIF('Question Set'!$G$178:$G$181,"In Progress"),IF(_xlpm.ip=0,"-",_xlpm.ip)) -> 2 | J36: =_xlfn.LET(_xlpm.y,COUNTIF('Question Set'!$G$178:$G$181,"Yes"),IF(_xlpm.y=0,"-",_xlpm.y)) -> - | K36: =N(H36)+(N(I36)*2)+(N(J36)*3) -> 4 | L36: of | M36: =(SUM(F36:J36)*3) -> 12
C37: Continuous Monitoring & Threat Detection | D37: 5 | E37: =_xlfn.LET(_xlpm.na,COUNTIF('Question Set'!$G$184:$G$188,"Not Applicable"),IF(_xlpm.na=0,"-",_xlpm.na)) -> - | F37: =_xlfn.LET(_xlpm.u,COUNTIF('Question Set'!$G$184:$G$188,"Unknown"),IF(_xlpm.u=0,"-",_xlpm.u)) -> - | G37: =_xlfn.LET(_xlpm.n,COUNTIF('Question Set'!$G$184:$G$188,"No"),IF(_xlpm.n=0,"-",_xlpm.n)) -> 3 | H37: =_xlfn.LET(_xlpm.pl,COUNTIF('Question Set'!$G$184:$G$188,"Planned"),IF(_xlpm.pl=0,"-",_xlpm.pl)) -> - | I37: =_xlfn.LET(_xlpm.ip,COUNTIF('Question Set'!$G$184:$G$188,"In Progress"),IF(_xlpm.ip=0,"-",_xlpm.ip)) -> 2 | J37: =_xlfn.LET(_xlpm.y,COUNTIF('Question Set'!$G$184:$G$188,"Yes"),IF(_xlpm.y=0,"-",_xlpm.y)) -> - | K37: =N(H37)+(N(I37)*2)+(N(J37)*3) -> 4 | L37: of | M37: =(SUM(F37:J37)*3) -> 15
C38: Security Event Review & Detection | D38: 4 | E38: =_xlfn.LET(_xlpm.na,COUNTIF('Question Set'!$G$191:$G$194,"Not Applicable"),IF(_xlpm.na=0,"-",_xlpm.na)) -> - | F38: =_xlfn.LET(_xlpm.u,COUNTIF('Question Set'!$G$191:$G$194,"Unknown"),IF(_xlpm.u=0,"-",_xlpm.u)) -> - | G38: =_xlfn.LET(_xlpm.n,COUNTIF('Question Set'!$G$191:$G$194,"No"),IF(_xlpm.n=0,"-",_xlpm.n)) -> 3 | H38: =_xlfn.LET(_xlpm.pl,COUNTIF('Question Set'!$G$191:$G$194,"Planned"),IF(_xlpm.pl=0,"-",_xlpm.pl)) -> - | I38: =_xlfn.LET(_xlpm.ip,COUNTIF('Question Set'!$G$191:$G$194,"In Progress"),IF(_xlpm.ip=0,"-",_xlpm.ip)) -> 1 | J38: =_xlfn.LET(_xlpm.y,COUNTIF('Question Set'!$G$191:$G$194,"Yes"),IF(_xlpm.y=0,"-",_xlpm.y)) -> - | K38: =N(H38)+(N(I38)*2)+(N(J38)*3) -> 2 | L38: of | M38: =(SUM(F38:J38)*3) -> 12
C39: Time Synchronization & Log Integrity | D39: 2 | E39: =_xlfn.LET(_xlpm.na,COUNTIF('Question Set'!$G$197:$G$198,"Not Applicable"),IF(_xlpm.na=0,"-",_xlpm.na)) -> - | F39: =_xlfn.LET(_xlpm.u,COUNTIF('Question Set'!$G$197:$G$198,"Unknown"),IF(_xlpm.u=0,"-",_xlpm.u)) -> - | G39: =_xlfn.LET(_xlpm.n,COUNTIF('Question Set'!$G$197:$G$198,"No"),IF(_xlpm.n=0,"-",_xlpm.n)) -> 1 | H39: =_xlfn.LET(_xlpm.pl,COUNTIF('Question Set'!$G$197:$G$198,"Planned"),IF(_xlpm.pl=0,"-",_xlpm.pl)) -> - | I39: =_xlfn.LET(_xlpm.ip,COUNTIF('Question Set'!$G$197:$G$198,"In Progress"),IF(_xlpm.ip=0,"-",_xlpm.ip)) -> 1 | J39: =_xlfn.LET(_xlpm.y,COUNTIF('Question Set'!$G$197:$G$198,"Yes"),IF(_xlpm.y=0,"-",_xlpm.y)) -> - | K39: =N(H39)+(N(I39)*2)+(N(J39)*3) -> 2 | L39: of | M39: =(SUM(F39:J39)*3) -> 6
C40: Domain Total | D40: =SUM(D36:D39) -> 15 | E40: =_xlfn.LET(_xlpm.x,SUM(E36:E39),IF(_xlpm.x=0,"-",_xlpm.x)) -> - | F40: =_xlfn.LET(_xlpm.x,SUM(F36:F39),IF(_xlpm.x=0,"-",_xlpm.x)) -> - | G40: =_xlfn.LET(_xlpm.x,SUM(G36:G39),IF(_xlpm.x=0,"-",_xlpm.x)) -> 9 | H40: =_xlfn.LET(_xlpm.x,SUM(H36:H39),IF(_xlpm.x=0,"-",_xlpm.x)) -> - | I40: =_xlfn.LET(_xlpm.x,SUM(I36:I39),IF(_xlpm.x=0,"-",_xlpm.x)) -> 6 | J40: =_xlfn.LET(_xlpm.x,SUM(J36:J39),IF(_xlpm.x=0,"-",_xlpm.x)) -> - | K40: =N(H40)+(N(I40)*2)+(N(J40)*3) -> 12 | L40: of | M40: =(SUM(F40:J40)*3) -> 45
B41: Response, Recovery & Forensic Readiness | C41: Incident Response Planning & Procedures | D41: 2 | E41: =_xlfn.LET(_xlpm.na,COUNTIF('Question Set'!$G$202:$G$203,"Not Applicable"),IF(_xlpm.na=0,"-",_xlpm.na)) -> - | F41: =_xlfn.LET(_xlpm.u,COUNTIF('Question Set'!$G$202:$G$203,"Unknown"),IF(_xlpm.u=0,"-",_xlpm.u)) -> - | G41: =_xlfn.LET(_xlpm.n,COUNTIF('Question Set'!$G$202:$G$203,"No"),IF(_xlpm.n=0,"-",_xlpm.n)) -> - | H41: =_xlfn.LET(_xlpm.pl,COUNTIF('Question Set'!$G$202:$G$203,"Planned"),IF(_xlpm.pl=0,"-",_xlpm.pl)) -> 1 | I41: =_xlfn.LET(_xlpm.ip,COUNTIF('Question Set'!$G$202:$G$203,"In Progress"),IF(_xlpm.ip=0,"-",_xlpm.ip)) -> 1 | J41: =_xlfn.LET(_xlpm.y,COUNTIF('Question Set'!$G$202:$G$203,"Yes"),IF(_xlpm.y=0,"-",_xlpm.y)) -> - | K41: =N(H41)+(N(I41)*2)+(N(J41)*3) -> 3 | L41: of | M41: =(SUM(F41:J41)*3) -> 6
...

Sheet Domain-Level Score Table
B2: Domain | C2: Not Applicable | D2: Unknown | E2: No | F2: Planned | G2: In Progress | H2: Yes | I2: Points | J2: of possible | K2: TOTAL
B3: Governance, Risk & Strategy | C3: ='Full Score Table'!E8 -> - | D3: ='Full Score Table'!F8 -> - | E3: ='Full Score Table'!G8 -> 7 | F3: ='Full Score Table'!H8 -> 1 | G3: ='Full Score Table'!I8 -> 2 | H3: ='Full Score Table'!J8 -> 6 | I3: ='Full Score Table'!K8 -> 23 | J3: of | K3: ='Full Score Table'!M8 -> 48
B4: Identity, Authentication & Access Management | C4: ='Full Score Table'!E15 -> - | D4: ='Full Score Table'!F15 -> 1 | E4: ='Full Score Table'!G15 -> 9 | F4: ='Full Score Table'!H15 -> - | G4: ='Full Score Table'!I15 -> 13 | H4: ='Full Score Table'!J15 -> 7 | I4: ='Full Score Table'!K15 -> 47 | J4: of | K4: ='Full Score Table'!M15 -> 90
B5: Data Security & Lifecycle Management | C5: ='Full Score Table'!E19 -> - | D5: ='Full Score Table'!F19 -> - | E5: ='Full Score Table'!G19 -> 3 | F5: ='Full Score Table'!H19 -> 2 | G5: ='Full Score Table'!I19 -> 5 | H5: ='Full Score Table'!J19 -> 2 | I5: ='Full Score Table'!K19 -> 18 | J5: of | K5: ='Full Score Table'!M19 -> 36
B6: Network & Communications Governance | C6: ='Full Score Table'!E26 -> 2 | D6: ='Full Score Table'!F26 -> 3 | E6: ='Full Score Table'!G26 -> 8 | F6: ='Full Score Table'!H26 -> 3 | G6: ='Full Score Table'!I26 -> 9 | H6: ='Full Score Table'!J26 -> 4 | I6: ='Full Score Table'!K26 -> 33 | J6: of | K6: ='Full Score Table'!M26 -> 81
B7: Endpoint Security & Configuration Management | C7: ='Full Score Table'!E31 -> 3 | D7: ='Full Score Table'!F31 -> - | E7: ='Full Score Table'!G31 -> 8 | F7: ='Full Score Table'!H31 -> 1 | G7: ='Full Score Table'!I31 -> 1 | H7: ='Full Score Table'!J31 -> 6 | I7: ='Full Score Table'!K31 -> 21 | J7: of | K7: ='Full Score Table'!M31 -> 48
B8: Cryptography, Encryption & Key Management Governance | C8: ='Full Score Table'!E35 -> 1 | D8: ='Full Score Table'!F35 -> 1 | E8: ='Full Score Table'!G35 -> 8 | F8: ='Full Score Table'!H35 -> - | G8: ='Full Score Table'!I35 -> - | H8: ='Full Score Table'!J35 -> - | I8: ='Full Score Table'!K35 -> 0 | J8: of | K8: ='Full Score Table'!M35 -> 27
B9: Logging, Monitoring & Event Detection | C9: ='Full Score Table'!E40 -> - | D9: ='Full Score Table'!F40 -> - | E9: ='Full Score Table'!G40 -> 9 | F9: ='Full Score Table'!H40 -> - | G9: ='Full Score Table'!I40 -> 6 | H9: ='Full Score Table'!J40 -> - | I9: ='Full Score Table'!K40 -> 12 | J9: of | K9: ='Full Score Table'!M40 -> 45
B10: Response, Recovery & Forensic Readiness | C10: ='Full Score Table'!E44 -> - | D10: ='Full Score Table'!F44 -> - | E10: ='Full Score Table'!G44 -> 2 | F10: ='Full Score Table'!H44 -> 2 | G10: ='Full Score Table'!I44 -> 4 | H10: ='Full Score Table'!J44 -> 2 | I10: ='Full Score Table'!K44 -> 16 | J10: of | K10: ='Full Score Table'!M44 -> 30
B11: Business Continuity & Environmental Resilience | C11: ='Full Score Table'!E49 -> 1 | D11: ='Full Score Table'!F49 -> 1 | E11: ='Full Score Table'!G49 -> - | F11: ='Full Score Table'!H49 -> 2 | G11: ='Full Score Table'!I49 -> 10 | H11: ='Full Score Table'!J49 -> 1 | I11: ='Full Score Table'!K49 -> 25 | J11: of | K11: ='Full Score Table'!M49 -> 42
B12: Physical & Environmental Security Management | C12: ='Full Score Table'!E55 -> 1 | D12: ='Full Score Table'!F55 -> - | E12: ='Full Score Table'!G55 -> 7 | F12: ='Full Score Table'!H55 -> - | G12: ='Full Score Table'!I55 -> 4 | H12: ='Full Score Table'!J55 -> 6 | I12: ='Full Score Table'!K55 -> 26 | J12: of | K12: ='Full Score Table'!M55 -> 51
B13: Third-Party Security & Supply Chain Management | C13: ='Full Score Table'!E60 -> - | D13: ='Full Score Table'!F60 -> - | E13: ='Full Score Table'!G60 -> 4 | F13: ='Full Score Table'!H60 -> 3 | G13: ='Full Score Table'!I60 -> - | H13: ='Full Score Table'!J60 -> - | I13: ='Full Score Table'!K60 -> 3 | J13: of | K13: ='Full Score Table'!M60 -> 21
B14: Assessment, Testing & Remediation Management | C14: ='Full Score Table'!E63 -> - | D14: ='Full Score Table'!F63 -> 1 | E14: ='Full Score Table'!G63 -> 4 | F14: ='Full Score Table'!H63 -> - | G14: ='Full Score Table'!I63 -> - | H14: ='Full Score Table'!J63 -> 1 | I14: ='Full Score Table'!K63 -> 3 | J14: of | K14: ='Full Score Table'!M63 -> 18
B15: Training, Awareness & Behavioral Governance | C15: ='Full Score Table'!E67 -> 1 | D15: ='Full Score Table'!F67 -> - | E15: ='Full Score Table'!G67 -> 3 | F15: ='Full Score Table'!H67 -> 1 | G15: ='Full Score Table'!I67 -> 1 | H15: ='Full Score Table'!J67 -> 5 | I15: ='Full Score Table'!K67 -> 18 | J15: of | K15: ='Full Score Table'!M67 -> 30
B16: OVERALL | C16: ='Full Score Table'!E3 -> 9 | D16: ='Full Score Table'!F3 -> 7 | E16: ='Full Score Table'!G3 -> 72 | F16: ='Full Score Table'!H3 -> 15 | G16: ='Full Score Table'!I3 -> 55 | H16: ='Full Score Table'!J3 -> 40 | I16: ='Full Score Table'!K3 -> 245 | J16: of | K16: ='Full Score Table'!M3 -> 567

Sheet -HIDE- Drop Downs | Maths
A1: - SELECT RATING - | N1: ('Question Set'!$G
L2: Ranges:
A3: YES | L3: 1. Governance, Risk & Strategy | N3: 2-25
A4: IN PROGRESS | M4: A. Executive Leadership & Resource Allocation | N4: 4-6
A5: PLANNED | M5: B. Policy & Asset Inventory Management | N5: 9-11
A6: NO | M6: C. Role Definition & Governance Oversight | N6: 14-18
A7: - | M7: D. Risk Assessment & Management Strategy | N7: 21-25
A8: UNKNOWN
A9: NOT APPLICABLE | L9: 2. Identity, Authentication & Access Management | N9: 27-68
M10: A. Access Control Governance & Management | N10: 29-34
M11: B. Account & Credential Lifecycle Management | N11: 37-41
M12: C. Authentication & Credential Governance | N12: 44-48
M13: D. Authorization & Least Privilege Enforcement | N13: 51-54
M14: E. Privileged Access Governance & Monitoring | N14: 57-61
A15: E-J | C15: Points | D15: Possible | E15: Percent | M15: F. Session Management & Monitoring | N15: 64-68
A16: 8 | B16: =_xlfn.CONCAT(F16, " (",G16, ")") -> Governance, Risk & Strategy (23 of 48) | C16: ='Domain-Level Score Table'!I3 -> 23 | D16: ='Domain-Level Score Table'!K3 -> 48 | E16: =C16/D16 -> 0.47916667 | F16: Governance, Risk & Strategy | G16: =_xlfn.CONCAT(C16, " of ", D16) -> 23 of 48
A17: 15 | B17: =_xlfn.CONCAT(F17, " (",G17, ")") -> Identity, Authentication & Access Management (47 of 90) | C17: ='Domain-Level Score Table'!I4 -> 47 | D17: ='Domain-Level Score Table'!K4 -> 90 | E17: =C17/D17 -> 0.52222222 | F17: Identity, Authentication & Access Management | G17: =_xlfn.CONCAT(C17, " of ", D17) -> 47 of 90 | L17: 3. Data Security & Lifecycle Management | N17: 70-87
A18: 19 | B18: =_xlfn.CONCAT(F18, " (",G18, ")") -> Data Security & Lifecycle Management (18 of 36) | C18: ='Domain-Level Score Table'!I5 -> 18 | D18: ='Domain-Level Score Table'!K5 -> 36 | E18: =C18/D18 -> 0.5 | F18: Data Security & Lifecycle Management | G18: =_xlfn.CONCAT(C18, " of ", D18) -> 18 of 36 | M18: A. Data Classification & Labelig | N18: 72-74
A19: 26 | B19: =_xlfn.CONCAT(F19, " (",G19, ")") -> Network & Communications Governance (33 of 81) | C19: ='Domain-Level Score Table'!I6 -> 33 | D19: ='Domain-Level Score Table'!K6 -> 81 | E19: =C19/D19 -> 0.40740741 | F19: Network & Communications Governance | G19: =_xlfn.CONCAT(C19, " of ", D19) -> 33 of 81 | M19: B. Data Protection & Lifecycle Management | N19: 77-82
A20: 31 | B20: =_xlfn.CONCAT(F20, " (",G20, ")") -> Endpoint Security & Configuration Management (21 of 48) | C20: ='Domain-Level Score Table'!I7 -> 21 | D20: ='Domain-Level Score Table'!K7 -> 48 | E20: =C20/D20 -> 0.4375 | F20: Endpoint Security & Configuration Management | G20: =_xlfn.CONCAT(C20, " of ", D20) -> 21 of 48 | M20: C. Data Access Monitoring & Disclosure Management | N20: 85-87
A21: 35 | B21: =_xlfn.CONCAT(F21, " (",G21, ")") -> Cryptography, Encryption & Key Management Governance (0 of 27) | C21: ='Domain-Level Score Table'!I8 -> 0 | D21: ='Domain-Level Score Table'!K8 -> 27 | E21: =C21/D21 -> 0 | F21: Cryptography, Encryption & Key Management Governance | G21: =_xlfn.CONCAT(C21, " of ", D21) -> 0 of 27
A22: 40 | B22: =_xlfn.CONCAT(F22, " (",G22, ")") -> Logging, Monitoring & Event Detection (12 of 45) | C22: ='Domain-Level Score Table'!I9 -> 12 | D22: ='Domain-Level Score Table'!K9 -> 45 | E22: =C22/D22 -> 0.26666667 | F22: Logging, Monitoring & Event Detection | G22: =_xlfn.CONCAT(C22, " of ", D22) -> 12 of 45 | L22: 4. Network & Communications Governance | N22: 89-129
A23: 44 | B23: =_xlfn.CONCAT(F23, " (",G23, ")") -> Response, Recovery & Forensic Readiness (16 of 30) | C23: ='Domain-Level Score Table'!I10 -> 16 | D23: ='Domain-Level Score Table'!K10 -> 30 | E23: =C23/D23 -> 0.53333333 | F23: Response, Recovery & Forensic Readiness | G23: =_xlfn.CONCAT(C23, " of ", D23) -> 16 of 30 | M23: A. Network Infrastructure & Boundary Controls | N23: 91-95
A24: 49 | B24: =_xlfn.CONCAT(F24, " (",G24, ")") -> Business Continuity & Environmental Resilience (25 of 42) | C24: ='Domain-Level Score Table'!I11 -> 25 | D24: ='Domain-Level Score Table'!K11 -> 42 | E24: =C24/D24 -> 0.5952381 | F24: Business Continuity & Environmental Resilience | G24: =_xlfn.CONCAT(C24, " of ", D24) -> 25 of 42 | M24: B. Network Traffic & Threat Controls | N24: 98-102
